2025-06-18 09:36:26,760 - SportsRecommendation - INFO - Démarrage du pipeline d'entraînement complet
2025-06-18 09:36:27,358 - SportsRecommendation - INFO -  MLflow configuré avec succès
2025-06-18 09:36:27,359 - SportsRecommendation - INFO - Chargement des données...
2025-06-18 09:36:28,788 - SportsRecommendation - INFO - Connexion à la base de données établie
2025-06-18 09:36:28,788 - SportsRecommendation - INFO - Chargement complet des données...
2025-06-18 09:36:28,788 - SportsRecommendation - INFO - Chargement des données utilisateurs...
2025-06-18 09:36:32,237 - SportsRecommendation - INFO - Chargement des événements (5 derniers jours)...
2025-06-18 09:37:52,557 - SportsRecommendation - INFO - Chargement des marchés...
2025-06-18 09:37:53,224 - SportsRecommendation - ERROR - Erreur requête SQL: (pymysql.err.OperationalError) (1054, "Unknown column 'market_type' in 'field list'")
[SQL: 
                SELECT market_id,                        event_id,                        market_name,                        market_type,                        status     as market_status,                        created_at as market_open_time
                FROM t_etl_market_with_outcomes_summary
                WHERE status IN ('open', 'suspended', 'closed')                 ]
(Background on this error at: https://sqlalche.me/e/20/e3q8)
2025-06-18 09:37:53,690 - SportsRecommendation - ERROR - Erreur lors du chargement des données: (pymysql.err.OperationalError) (1054, "Unknown column 'market_type' in 'field list'")
[SQL: 
                SELECT market_id,                        event_id,                        market_name,                        market_type,                        status     as market_status,                        created_at as market_open_time
                FROM t_etl_market_with_outcomes_summary
                WHERE status IN ('open', 'suspended', 'closed')                 ]
(Background on this error at: https://sqlalche.me/e/20/e3q8)
2025-06-18 09:37:53,864 - SportsRecommendation - INFO - Connexion DB fermée
2025-06-18 09:37:53,864 - SportsRecommendation - ERROR - ÉCHEC DU PIPELINE: (pymysql.err.OperationalError) (1054, "Unknown column 'market_type' in 'field list'")
[SQL: 
                SELECT market_id,                        event_id,                        market_name,                        market_type,                        status     as market_status,                        created_at as market_open_time
                FROM t_etl_market_with_outcomes_summary
                WHERE status IN ('open', 'suspended', 'closed')                 ]
(Background on this error at: https://sqlalche.me/e/20/e3q8)
2025-06-18 09:37:53,894 - SportsRecommendation - ERROR - Traceback: Traceback (most recent call last):
  File "/Users/krohn/PycharmProjects/betting_recommender/.venv/lib/python3.11/site-packages/sqlalchemy/engine/base.py", line 1963, in _exec_single_context
    self.dialect.do_execute(
  File "/Users/krohn/PycharmProjects/betting_recommender/.venv/lib/python3.11/site-packages/sqlalchemy/engine/default.py", line 943, in do_execute
    cursor.execute(statement, parameters)
  File "/Users/krohn/PycharmProjects/betting_recommender/.venv/lib/python3.11/site-packages/pymysql/cursors.py", line 153, in execute
    result = self._query(query)
             ^^^^^^^^^^^^^^^^^^
  File "/Users/krohn/PycharmProjects/betting_recommender/.venv/lib/python3.11/site-packages/pymysql/cursors.py", line 322, in _query
    conn.query(q)
  File "/Users/krohn/PycharmProjects/betting_recommender/.venv/lib/python3.11/site-packages/pymysql/connections.py", line 563, in query
    self._affected_rows = self._read_query_result(unbuffered=unbuffered)
                          ^^^^^^^^^^^^^^^^^^^^^^^^^^^^^^^^^^^^^^^^^^^^^^
  File "/Users/krohn/PycharmProjects/betting_recommender/.venv/lib/python3.11/site-packages/pymysql/connections.py", line 825, in _read_query_result
    result.read()
  File "/Users/krohn/PycharmProjects/betting_recommender/.venv/lib/python3.11/site-packages/pymysql/connections.py", line 1199, in read
    first_packet = self.connection._read_packet()
                   ^^^^^^^^^^^^^^^^^^^^^^^^^^^^^^
  File "/Users/krohn/PycharmProjects/betting_recommender/.venv/lib/python3.11/site-packages/pymysql/connections.py", line 775, in _read_packet
    packet.raise_for_error()
  File "/Users/krohn/PycharmProjects/betting_recommender/.venv/lib/python3.11/site-packages/pymysql/protocol.py", line 219, in raise_for_error
    err.raise_mysql_exception(self._data)
  File "/Users/krohn/PycharmProjects/betting_recommender/.venv/lib/python3.11/site-packages/pymysql/err.py", line 150, in raise_mysql_exception
    raise errorclass(errno, errval)
pymysql.err.OperationalError: (1054, "Unknown column 'market_type' in 'field list'")

The above exception was the direct cause of the following exception:

Traceback (most recent call last):
  File "/Users/krohn/PycharmProjects/betting_recommender/models/train.py", line 658, in run_full_pipeline
    self.load_data()
  File "/Users/krohn/PycharmProjects/betting_recommender/models/train.py", line 122, in load_data
    self.raw_data = self.data_loader.load_all_data(load_config)
                    ^^^^^^^^^^^^^^^^^^^^^^^^^^^^^^^^^^^^^^^^^^^
  File "/Users/krohn/PycharmProjects/betting_recommender/data/data_loader.py", line 170, in load_all_data
    'markets': self.load_markets_data(config.get('markets_limit')),
               ^^^^^^^^^^^^^^^^^^^^^^^^^^^^^^^^^^^^^^^^^^^^^^^^^^^
  File "/Users/krohn/PycharmProjects/betting_recommender/data/data_loader.py", line 86, in load_markets_data
    return self.db.execute_query(query)
           ^^^^^^^^^^^^^^^^^^^^^^^^^^^^
  File "/Users/krohn/PycharmProjects/betting_recommender/data/database_connector.py", line 64, in execute_query
    return pd.read_sql(query, self.engine)
           ^^^^^^^^^^^^^^^^^^^^^^^^^^^^^^^
  File "/Users/krohn/PycharmProjects/betting_recommender/.venv/lib/python3.11/site-packages/pandas/io/sql.py", line 734, in read_sql
    return pandas_sql.read_query(
           ^^^^^^^^^^^^^^^^^^^^^^
  File "/Users/krohn/PycharmProjects/betting_recommender/.venv/lib/python3.11/site-packages/pandas/io/sql.py", line 1836, in read_query
    result = self.execute(sql, params)
             ^^^^^^^^^^^^^^^^^^^^^^^^^
  File "/Users/krohn/PycharmProjects/betting_recommender/.venv/lib/python3.11/site-packages/pandas/io/sql.py", line 1659, in execute
    return self.con.exec_driver_sql(sql, *args)
           ^^^^^^^^^^^^^^^^^^^^^^^^^^^^^^^^^^^^
  File "/Users/krohn/PycharmProjects/betting_recommender/.venv/lib/python3.11/site-packages/sqlalchemy/engine/base.py", line 1775, in exec_driver_sql
    ret = self._execute_context(
          ^^^^^^^^^^^^^^^^^^^^^^
  File "/Users/krohn/PycharmProjects/betting_recommender/.venv/lib/python3.11/site-packages/sqlalchemy/engine/base.py", line 1842, in _execute_context
    return self._exec_single_context(
           ^^^^^^^^^^^^^^^^^^^^^^^^^^
  File "/Users/krohn/PycharmProjects/betting_recommender/.venv/lib/python3.11/site-packages/sqlalchemy/engine/base.py", line 1982, in _exec_single_context
    self._handle_dbapi_exception(
  File "/Users/krohn/PycharmProjects/betting_recommender/.venv/lib/python3.11/site-packages/sqlalchemy/engine/base.py", line 2351, in _handle_dbapi_exception
    raise sqlalchemy_exception.with_traceback(exc_info[2]) from e
  File "/Users/krohn/PycharmProjects/betting_recommender/.venv/lib/python3.11/site-packages/sqlalchemy/engine/base.py", line 1963, in _exec_single_context
    self.dialect.do_execute(
  File "/Users/krohn/PycharmProjects/betting_recommender/.venv/lib/python3.11/site-packages/sqlalchemy/engine/default.py", line 943, in do_execute
    cursor.execute(statement, parameters)
  File "/Users/krohn/PycharmProjects/betting_recommender/.venv/lib/python3.11/site-packages/pymysql/cursors.py", line 153, in execute
    result = self._query(query)
             ^^^^^^^^^^^^^^^^^^
  File "/Users/krohn/PycharmProjects/betting_recommender/.venv/lib/python3.11/site-packages/pymysql/cursors.py", line 322, in _query
    conn.query(q)
  File "/Users/krohn/PycharmProjects/betting_recommender/.venv/lib/python3.11/site-packages/pymysql/connections.py", line 563, in query
    self._affected_rows = self._read_query_result(unbuffered=unbuffered)
                          ^^^^^^^^^^^^^^^^^^^^^^^^^^^^^^^^^^^^^^^^^^^^^^
  File "/Users/krohn/PycharmProjects/betting_recommender/.venv/lib/python3.11/site-packages/pymysql/connections.py", line 825, in _read_query_result
    result.read()
  File "/Users/krohn/PycharmProjects/betting_recommender/.venv/lib/python3.11/site-packages/pymysql/connections.py", line 1199, in read
    first_packet = self.connection._read_packet()
                   ^^^^^^^^^^^^^^^^^^^^^^^^^^^^^^
  File "/Users/krohn/PycharmProjects/betting_recommender/.venv/lib/python3.11/site-packages/pymysql/connections.py", line 775, in _read_packet
    packet.raise_for_error()
  File "/Users/krohn/PycharmProjects/betting_recommender/.venv/lib/python3.11/site-packages/pymysql/protocol.py", line 219, in raise_for_error
    err.raise_mysql_exception(self._data)
  File "/Users/krohn/PycharmProjects/betting_recommender/.venv/lib/python3.11/site-packages/pymysql/err.py", line 150, in raise_mysql_exception
    raise errorclass(errno, errval)
sqlalchemy.exc.OperationalError: (pymysql.err.OperationalError) (1054, "Unknown column 'market_type' in 'field list'")
[SQL: 
                SELECT market_id,                        event_id,                        market_name,                        market_type,                        status     as market_status,                        created_at as market_open_time
                FROM t_etl_market_with_outcomes_summary
                WHERE status IN ('open', 'suspended', 'closed')                 ]
(Background on this error at: https://sqlalche.me/e/20/e3q8)

