2025-06-18 10:25:07,496 - SportsRecommendation - INFO - Démarrage du pipeline d'entraînement complet
2025-06-18 10:25:43,435 - SportsRecommendation - INFO -  MLflow configuré avec succès
2025-06-18 10:25:43,441 - SportsRecommendation - INFO - Chargement des données...
2025-06-18 10:25:48,855 - SportsRecommendation - INFO - Connexion à la base de données établie
2025-06-18 10:25:48,855 - SportsRecommendation - INFO - Chargement complet des données...
2025-06-18 10:25:48,855 - SportsRecommendation - INFO - Chargement des données utilisateurs...
2025-06-18 10:25:58,873 - SportsRecommendation - ERROR - Erreur requête SQL: (pymysql.err.OperationalError) (2003, "Can't connect to MySQL server on '146.59.148.113' (timed out)")
(Background on this error at: https://sqlalche.me/e/20/e3q8)
2025-06-18 10:25:58,874 - SportsRecommendation - ERROR - Erreur lors du chargement des données: (pymysql.err.OperationalError) (2003, "Can't connect to MySQL server on '146.59.148.113' (timed out)")
(Background on this error at: https://sqlalche.me/e/20/e3q8)
2025-06-18 10:25:59,065 - SportsRecommendation - INFO - Connexion DB fermée
2025-06-18 10:25:59,066 - SportsRecommendation - ERROR - ÉCHEC DU PIPELINE: (pymysql.err.OperationalError) (2003, "Can't connect to MySQL server on '146.59.148.113' (timed out)")
(Background on this error at: https://sqlalche.me/e/20/e3q8)
2025-06-18 10:25:59,089 - SportsRecommendation - ERROR - Traceback: Traceback (most recent call last):
  File "/Users/krohn/PycharmProjects/betting_recommender/.venv/lib/python3.11/site-packages/pymysql/connections.py", line 649, in connect
    sock = socket.create_connection(
           ^^^^^^^^^^^^^^^^^^^^^^^^^
  File "/Users/krohn/.pyenv/versions/3.11.9/lib/python3.11/socket.py", line 851, in create_connection
    raise exceptions[0]
  File "/Users/krohn/.pyenv/versions/3.11.9/lib/python3.11/socket.py", line 836, in create_connection
    sock.connect(sa)
TimeoutError: timed out

During handling of the above exception, another exception occurred:

Traceback (most recent call last):
  File "/Users/krohn/PycharmProjects/betting_recommender/.venv/lib/python3.11/site-packages/sqlalchemy/engine/base.py", line 145, in __init__
    self._dbapi_connection = engine.raw_connection()
                             ^^^^^^^^^^^^^^^^^^^^^^^
  File "/Users/krohn/PycharmProjects/betting_recommender/.venv/lib/python3.11/site-packages/sqlalchemy/engine/base.py", line 3297, in raw_connection
    return self.pool.connect()
           ^^^^^^^^^^^^^^^^^^^
  File "/Users/krohn/PycharmProjects/betting_recommender/.venv/lib/python3.11/site-packages/sqlalchemy/pool/base.py", line 449, in connect
    return _ConnectionFairy._checkout(self)
           ^^^^^^^^^^^^^^^^^^^^^^^^^^^^^^^^
  File "/Users/krohn/PycharmProjects/betting_recommender/.venv/lib/python3.11/site-packages/sqlalchemy/pool/base.py", line 1264, in _checkout
    fairy = _ConnectionRecord.checkout(pool)
            ^^^^^^^^^^^^^^^^^^^^^^^^^^^^^^^^
  File "/Users/krohn/PycharmProjects/betting_recommender/.venv/lib/python3.11/site-packages/sqlalchemy/pool/base.py", line 713, in checkout
    rec = pool._do_get()
          ^^^^^^^^^^^^^^
  File "/Users/krohn/PycharmProjects/betting_recommender/.venv/lib/python3.11/site-packages/sqlalchemy/pool/impl.py", line 179, in _do_get
    with util.safe_reraise():
  File "/Users/krohn/PycharmProjects/betting_recommender/.venv/lib/python3.11/site-packages/sqlalchemy/util/langhelpers.py", line 224, in __exit__
    raise exc_value.with_traceback(exc_tb)
  File "/Users/krohn/PycharmProjects/betting_recommender/.venv/lib/python3.11/site-packages/sqlalchemy/pool/impl.py", line 177, in _do_get
    return self._create_connection()
           ^^^^^^^^^^^^^^^^^^^^^^^^^
  File "/Users/krohn/PycharmProjects/betting_recommender/.venv/lib/python3.11/site-packages/sqlalchemy/pool/base.py", line 390, in _create_connection
    return _ConnectionRecord(self)
           ^^^^^^^^^^^^^^^^^^^^^^^
  File "/Users/krohn/PycharmProjects/betting_recommender/.venv/lib/python3.11/site-packages/sqlalchemy/pool/base.py", line 675, in __init__
    self.__connect()
  File "/Users/krohn/PycharmProjects/betting_recommender/.venv/lib/python3.11/site-packages/sqlalchemy/pool/base.py", line 901, in __connect
    with util.safe_reraise():
  File "/Users/krohn/PycharmProjects/betting_recommender/.venv/lib/python3.11/site-packages/sqlalchemy/util/langhelpers.py", line 224, in __exit__
    raise exc_value.with_traceback(exc_tb)
  File "/Users/krohn/PycharmProjects/betting_recommender/.venv/lib/python3.11/site-packages/sqlalchemy/pool/base.py", line 897, in __connect
    self.dbapi_connection = connection = pool._invoke_creator(self)
                                         ^^^^^^^^^^^^^^^^^^^^^^^^^^
  File "/Users/krohn/PycharmProjects/betting_recommender/.venv/lib/python3.11/site-packages/sqlalchemy/engine/create.py", line 646, in connect
    return dialect.connect(*cargs, **cparams)
           ^^^^^^^^^^^^^^^^^^^^^^^^^^^^^^^^^^
  File "/Users/krohn/PycharmProjects/betting_recommender/.venv/lib/python3.11/site-packages/sqlalchemy/engine/default.py", line 625, in connect
    return self.loaded_dbapi.connect(*cargs, **cparams)  # type: ignore[no-any-return]  # NOQA: E501
           ^^^^^^^^^^^^^^^^^^^^^^^^^^^^^^^^^^^^^^^^^^^^
  File "/Users/krohn/PycharmProjects/betting_recommender/.venv/lib/python3.11/site-packages/pymysql/connections.py", line 361, in __init__
    self.connect()
  File "/Users/krohn/PycharmProjects/betting_recommender/.venv/lib/python3.11/site-packages/pymysql/connections.py", line 716, in connect
    raise exc
pymysql.err.OperationalError: (2003, "Can't connect to MySQL server on '146.59.148.113' (timed out)")

The above exception was the direct cause of the following exception:

Traceback (most recent call last):
  File "/Users/krohn/PycharmProjects/betting_recommender/models/train.py", line 658, in run_full_pipeline
    self.load_data()
  File "/Users/krohn/PycharmProjects/betting_recommender/models/train.py", line 122, in load_data
    self.raw_data = self.data_loader.load_all_data(load_config)
                    ^^^^^^^^^^^^^^^^^^^^^^^^^^^^^^^^^^^^^^^^^^^
  File "/Users/krohn/PycharmProjects/betting_recommender/data/data_loader.py", line 164, in load_all_data
    'users': self.load_users_data(config.get('users_limit')),
             ^^^^^^^^^^^^^^^^^^^^^^^^^^^^^^^^^^^^^^^^^^^^^^^
  File "/Users/krohn/PycharmProjects/betting_recommender/data/data_loader.py", line 36, in load_users_data
    return self.db.execute_query(query)
           ^^^^^^^^^^^^^^^^^^^^^^^^^^^^
  File "/Users/krohn/PycharmProjects/betting_recommender/data/database_connector.py", line 64, in execute_query
    return pd.read_sql(query, self.engine)
           ^^^^^^^^^^^^^^^^^^^^^^^^^^^^^^^
  File "/Users/krohn/PycharmProjects/betting_recommender/.venv/lib/python3.11/site-packages/pandas/io/sql.py", line 704, in read_sql
    with pandasSQL_builder(con) as pandas_sql:
         ^^^^^^^^^^^^^^^^^^^^^^
  File "/Users/krohn/PycharmProjects/betting_recommender/.venv/lib/python3.11/site-packages/pandas/io/sql.py", line 906, in pandasSQL_builder
    return SQLDatabase(con, schema, need_transaction)
           ^^^^^^^^^^^^^^^^^^^^^^^^^^^^^^^^^^^^^^^^^^
  File "/Users/krohn/PycharmProjects/betting_recommender/.venv/lib/python3.11/site-packages/pandas/io/sql.py", line 1636, in __init__
    con = self.exit_stack.enter_context(con.connect())
                                        ^^^^^^^^^^^^^
  File "/Users/krohn/PycharmProjects/betting_recommender/.venv/lib/python3.11/site-packages/sqlalchemy/engine/base.py", line 3273, in connect
    return self._connection_cls(self)
           ^^^^^^^^^^^^^^^^^^^^^^^^^^
  File "/Users/krohn/PycharmProjects/betting_recommender/.venv/lib/python3.11/site-packages/sqlalchemy/engine/base.py", line 147, in __init__
    Connection._handle_dbapi_exception_noconnection(
  File "/Users/krohn/PycharmProjects/betting_recommender/.venv/lib/python3.11/site-packages/sqlalchemy/engine/base.py", line 2436, in _handle_dbapi_exception_noconnection
    raise sqlalchemy_exception.with_traceback(exc_info[2]) from e
  File "/Users/krohn/PycharmProjects/betting_recommender/.venv/lib/python3.11/site-packages/sqlalchemy/engine/base.py", line 145, in __init__
    self._dbapi_connection = engine.raw_connection()
                             ^^^^^^^^^^^^^^^^^^^^^^^
  File "/Users/krohn/PycharmProjects/betting_recommender/.venv/lib/python3.11/site-packages/sqlalchemy/engine/base.py", line 3297, in raw_connection
    return self.pool.connect()
           ^^^^^^^^^^^^^^^^^^^
  File "/Users/krohn/PycharmProjects/betting_recommender/.venv/lib/python3.11/site-packages/sqlalchemy/pool/base.py", line 449, in connect
    return _ConnectionFairy._checkout(self)
           ^^^^^^^^^^^^^^^^^^^^^^^^^^^^^^^^
  File "/Users/krohn/PycharmProjects/betting_recommender/.venv/lib/python3.11/site-packages/sqlalchemy/pool/base.py", line 1264, in _checkout
    fairy = _ConnectionRecord.checkout(pool)
            ^^^^^^^^^^^^^^^^^^^^^^^^^^^^^^^^
  File "/Users/krohn/PycharmProjects/betting_recommender/.venv/lib/python3.11/site-packages/sqlalchemy/pool/base.py", line 713, in checkout
    rec = pool._do_get()
          ^^^^^^^^^^^^^^
  File "/Users/krohn/PycharmProjects/betting_recommender/.venv/lib/python3.11/site-packages/sqlalchemy/pool/impl.py", line 179, in _do_get
    with util.safe_reraise():
  File "/Users/krohn/PycharmProjects/betting_recommender/.venv/lib/python3.11/site-packages/sqlalchemy/util/langhelpers.py", line 224, in __exit__
    raise exc_value.with_traceback(exc_tb)
  File "/Users/krohn/PycharmProjects/betting_recommender/.venv/lib/python3.11/site-packages/sqlalchemy/pool/impl.py", line 177, in _do_get
    return self._create_connection()
           ^^^^^^^^^^^^^^^^^^^^^^^^^
  File "/Users/krohn/PycharmProjects/betting_recommender/.venv/lib/python3.11/site-packages/sqlalchemy/pool/base.py", line 390, in _create_connection
    return _ConnectionRecord(self)
           ^^^^^^^^^^^^^^^^^^^^^^^
  File "/Users/krohn/PycharmProjects/betting_recommender/.venv/lib/python3.11/site-packages/sqlalchemy/pool/base.py", line 675, in __init__
    self.__connect()
  File "/Users/krohn/PycharmProjects/betting_recommender/.venv/lib/python3.11/site-packages/sqlalchemy/pool/base.py", line 901, in __connect
    with util.safe_reraise():
  File "/Users/krohn/PycharmProjects/betting_recommender/.venv/lib/python3.11/site-packages/sqlalchemy/util/langhelpers.py", line 224, in __exit__
    raise exc_value.with_traceback(exc_tb)
  File "/Users/krohn/PycharmProjects/betting_recommender/.venv/lib/python3.11/site-packages/sqlalchemy/pool/base.py", line 897, in __connect
    self.dbapi_connection = connection = pool._invoke_creator(self)
                                         ^^^^^^^^^^^^^^^^^^^^^^^^^^
  File "/Users/krohn/PycharmProjects/betting_recommender/.venv/lib/python3.11/site-packages/sqlalchemy/engine/create.py", line 646, in connect
    return dialect.connect(*cargs, **cparams)
           ^^^^^^^^^^^^^^^^^^^^^^^^^^^^^^^^^^
  File "/Users/krohn/PycharmProjects/betting_recommender/.venv/lib/python3.11/site-packages/sqlalchemy/engine/default.py", line 625, in connect
    return self.loaded_dbapi.connect(*cargs, **cparams)  # type: ignore[no-any-return]  # NOQA: E501
           ^^^^^^^^^^^^^^^^^^^^^^^^^^^^^^^^^^^^^^^^^^^^
  File "/Users/krohn/PycharmProjects/betting_recommender/.venv/lib/python3.11/site-packages/pymysql/connections.py", line 361, in __init__
    self.connect()
  File "/Users/krohn/PycharmProjects/betting_recommender/.venv/lib/python3.11/site-packages/pymysql/connections.py", line 716, in connect
    raise exc
sqlalchemy.exc.OperationalError: (pymysql.err.OperationalError) (2003, "Can't connect to MySQL server on '146.59.148.113' (timed out)")
(Background on this error at: https://sqlalche.me/e/20/e3q8)

